{
  "id": "RUSTSEC-2020-0074",
  "modified": "2021-01-04T17:02:59+00:00",
  "published": "2020-11-28T12:00:00+00:00",
  "aliases": [
    "CVE-2020-35917"
  ],
  "related": [],
  "summary": "Reference counting error in `From<Py<T>>`",
  "details": "A bug in `From<Py<T>>` would lead to an extra reference count decrement, often\nleading to use-after-free issues.",
  "affected": [
    {
      "package": {
        "ecosystem": "crates.io",
        "name": "pyo3",
        "purl": "pkg:cargo/pyo3"
      },
      "ecosystem_specific": {
        "affects": {
          "arch": [],
          "os": [],
          "functions": []
        }
      },
      "database_specific": {
        "categories": [],
        "cvss": null,
        "informational": null
      },
      "ranges": [
        {
          "type": "SEMVER",
          "events": [
            {
              "introduced": "0.12.0"
            },
            {
              "fixed": "0.12.4"
            }
          ]
        }
      ]
    }
  ],
  "references": [
    {
      "type": "PACKAGE",
      "url": "https://crates.io/crates/pyo3"
    },
    {
      "type": "ADVISORY",
      "url": "https://rustsec.org/advisories/RUSTSEC-2020-0074.html"
    },
    {
      "type": "WEB",
      "url": "https://github.com/PyO3/pyo3/pull/1297"
    }
  ]
}